[2024-03-01 13:05:04,797: INFO: main: Welcome to our custom log]
[2024-03-01 14:45:57,134: INFO: common: yaml file: E:\KidneyDiseaseclassfication\config\config.yaml loaded successfully]
[2024-03-01 14:45:57,144: INFO: common: yaml file: E:\KidneyDiseaseclassfication\params.yaml loaded successfully]
[2024-03-01 14:45:57,151: INFO: common: created directory at: artifacts/data_ingestion]
[2024-03-01 14:45:57,154: INFO: 3172177572: Downloading data from https://drive.google.com/file/d/1vlhZ5c7abUKF8xXERIw6m9Te8fW7ohw3/view?usp=sharing into file artifacts/data_ingestion/data.zip]
[2024-03-01 14:46:44,469: INFO: 3172177572: Downloaded data from https://drive.google.com/file/d/1vlhZ5c7abUKF8xXERIw6m9Te8fW7ohw3/view?usp=sharing into file artifacts/data_ingestion/data.zip]
[2024-03-01 15:04:04,704: INFO: common: yaml file: E:\KidneyDiseaseclassfication\config\config.yaml loaded successfully]
[2024-03-01 15:04:04,712: INFO: common: yaml file: E:\KidneyDiseaseclassfication\params.yaml loaded successfully]
[2024-03-01 15:04:04,717: INFO: common: created directory at: artifacts/data_ingestion]
[2024-03-01 15:04:04,722: INFO: 3172177572: Downloading data from https://drive.google.com/file/d/1vlhZ5c7abUKF8xXERIw6m9Te8fW7ohw3/view?usp=sharing into file artifacts/data_ingestion/data.zip]
[2024-03-01 15:04:58,026: INFO: 3172177572: Downloaded data from https://drive.google.com/file/d/1vlhZ5c7abUKF8xXERIw6m9Te8fW7ohw3/view?usp=sharing into file artifacts/data_ingestion/data.zip]
[2024-03-01 15:09:57,384: INFO: common: yaml file: E:\KidneyDiseaseclassfication\config\config.yaml loaded successfully]
[2024-03-01 15:09:57,390: INFO: common: yaml file: E:\KidneyDiseaseclassfication\params.yaml loaded successfully]
[2024-03-01 15:09:57,393: INFO: common: created directory at: artifacts/data_ingestion]
[2024-03-01 15:09:57,398: INFO: 3172177572: Downloading data from https://drive.google.com/file/d/1vlhZ5c7abUKF8xXERIw6m9Te8fW7ohw3/view?usp=sharing into file KidneyDiseaseclassfication/research/artifacts/data_ingestion/data.zip]
[2024-03-01 15:10:39,221: INFO: common: yaml file: E:\KidneyDiseaseclassfication\config\config.yaml loaded successfully]
[2024-03-01 15:10:39,229: INFO: common: yaml file: E:\KidneyDiseaseclassfication\params.yaml loaded successfully]
[2024-03-01 15:10:39,231: INFO: common: created directory at: artifacts/data_ingestion]
[2024-03-01 15:10:39,236: INFO: 2401468353: Downloading data from https://drive.google.com/file/d/1vlhZ5c7abUKF8xXERIw6m9Te8fW7ohw3/view?usp=sharing into file KidneyDiseaseclassfication/research/artifacts/data_ingestion/data.zip]
[2024-03-01 15:11:30,695: INFO: 2401468353: Downloaded data from https://drive.google.com/file/d/1vlhZ5c7abUKF8xXERIw6m9Te8fW7ohw3/view?usp=sharing into file KidneyDiseaseclassfication/research/artifacts/data_ingestion/data.zip]
[2024-03-01 15:14:09,246: INFO: common: yaml file: E:\KidneyDiseaseclassfication\config\config.yaml loaded successfully]
[2024-03-01 15:14:09,255: INFO: common: yaml file: E:\KidneyDiseaseclassfication\params.yaml loaded successfully]
[2024-03-01 15:14:09,259: INFO: common: created directory at: artifacts/data_ingestion]
[2024-03-01 15:14:09,261: INFO: 2401468353: Downloading data from https://drive.google.com/file/d/1vlhZ5c7abUKF8xXERIw6m9Te8fW7ohw3/view?usp=sharing into file KidneyDiseaseclassfication/research/artifacts/data_ingestion/data.zip]
[2024-03-01 15:14:54,582: INFO: 2401468353: Downloaded data from https://drive.google.com/file/d/1vlhZ5c7abUKF8xXERIw6m9Te8fW7ohw3/view?usp=sharing into file KidneyDiseaseclassfication/research/artifacts/data_ingestion/data.zip]
[2024-03-01 15:31:27,673: INFO: main: >>>>>> stage Data Ingestion stage started <<<<<<]
[2024-03-01 15:31:27,677: INFO: common: yaml file: config\config.yaml loaded successfully]
[2024-03-01 15:31:27,681: INFO: common: yaml file: params.yaml loaded successfully]
[2024-03-01 15:31:27,683: INFO: common: created directory at: artifacts]
[2024-03-01 15:31:27,683: INFO: common: created directory at: artifacts/data_ingestion]
[2024-03-01 15:31:27,685: INFO: data_ingestion: Downloading data from https://drive.google.com/file/d/1vlhZ5c7abUKF8xXERIw6m9Te8fW7ohw3/view?usp=sharing into file KidneyDiseaseclassfication/research/artifacts/data_ingestion/data.zip]
[2024-03-01 15:31:56,058: INFO: data_ingestion: Downloaded data from https://drive.google.com/file/d/1vlhZ5c7abUKF8xXERIw6m9Te8fW7ohw3/view?usp=sharing into file KidneyDiseaseclassfication/research/artifacts/data_ingestion/data.zip]
[2024-03-01 15:31:57,281: INFO: main: >>>>>> stage Data Ingestion stage completed <<<<<<

x==========x]
[2024-03-01 15:36:34,784: INFO: main: >>>>>> stage Data Ingestion stage started <<<<<<]
[2024-03-01 15:36:34,795: INFO: common: yaml file: config\config.yaml loaded successfully]
[2024-03-01 15:36:34,796: INFO: common: yaml file: params.yaml loaded successfully]
[2024-03-01 15:36:34,798: INFO: common: created directory at: artifacts]
[2024-03-01 15:36:34,799: INFO: common: created directory at: artifacts/data_ingestion]
[2024-03-01 15:36:34,801: INFO: data_ingestion: Downloading data from https://drive.google.com/file/d/1vlhZ5c7abUKF8xXERIw6m9Te8fW7ohw3/view?usp=sharing into file KidneyDiseaseclassfication/research/artifacts/data_ingestion/data.zip]
[2024-03-01 15:37:07,217: INFO: data_ingestion: Downloaded data from https://drive.google.com/file/d/1vlhZ5c7abUKF8xXERIw6m9Te8fW7ohw3/view?usp=sharing into file KidneyDiseaseclassfication/research/artifacts/data_ingestion/data.zip]
[2024-03-01 15:37:08,139: INFO: main: >>>>>> stage Data Ingestion stage completed <<<<<<

x==========x]
[2024-03-01 15:38:27,725: INFO: main: >>>>>> stage Data Ingestion stage started <<<<<<]
[2024-03-01 15:38:27,732: INFO: common: yaml file: config\config.yaml loaded successfully]
[2024-03-01 15:38:27,736: INFO: common: yaml file: params.yaml loaded successfully]
[2024-03-01 15:38:27,737: INFO: common: created directory at: artifacts]
[2024-03-01 15:38:27,738: INFO: common: created directory at: artifacts/data_ingestion]
[2024-03-01 15:38:27,744: INFO: data_ingestion: Downloading data from https://drive.google.com/file/d/1vlhZ5c7abUKF8xXERIw6m9Te8fW7ohw3/view?usp=sharing into file artifacts/data_ingestion/data.zip]
[2024-03-01 15:38:56,686: INFO: data_ingestion: Downloaded data from https://drive.google.com/file/d/1vlhZ5c7abUKF8xXERIw6m9Te8fW7ohw3/view?usp=sharing into file artifacts/data_ingestion/data.zip]
[2024-03-01 15:38:57,657: INFO: main: >>>>>> stage Data Ingestion stage completed <<<<<<

x==========x]
[2024-03-01 15:40:09,381: INFO: main: >>>>>> stage Data Ingestion stage started <<<<<<]
[2024-03-01 15:40:09,383: INFO: common: yaml file: config\config.yaml loaded successfully]
[2024-03-01 15:40:09,385: INFO: common: yaml file: params.yaml loaded successfully]
[2024-03-01 15:40:09,386: INFO: common: created directory at: artifacts]
[2024-03-01 15:40:09,387: INFO: common: created directory at: artifacts/data_ingestion]
[2024-03-01 15:40:09,390: INFO: data_ingestion: Downloading data from https://drive.google.com/file/d/1vlhZ5c7abUKF8xXERIw6m9Te8fW7ohw3/view?usp=sharing into file artifacts/data_ingestion/data.zip]
[2024-03-01 15:43:49,374: INFO: main: >>>>>> stage Data Ingestion stage started <<<<<<]
[2024-03-01 15:43:49,377: INFO: common: yaml file: config\config.yaml loaded successfully]
[2024-03-01 15:43:49,380: INFO: common: yaml file: params.yaml loaded successfully]
[2024-03-01 15:43:49,381: INFO: common: created directory at: artifacts]
[2024-03-01 15:43:49,382: INFO: common: created directory at: artifacts/data_ingestion]
[2024-03-01 15:43:49,383: INFO: data_ingestion: Downloading data from https://drive.google.com/file/d/1vlhZ5c7abUKF8xXERIw6m9Te8fW7ohw3/view?usp=sharing into file artifacts/data_ingestion/data.zip]
[2024-03-01 15:50:32,085: INFO: main: >>>>>> stage Data Ingestion stage started <<<<<<]
[2024-03-01 15:50:32,088: INFO: common: yaml file: config\config.yaml loaded successfully]
[2024-03-01 15:50:32,090: INFO: common: yaml file: params.yaml loaded successfully]
[2024-03-01 15:50:32,091: INFO: common: created directory at: artifacts]
[2024-03-01 15:50:32,091: INFO: common: created directory at: artifacts/data_ingestion]
[2024-03-01 15:50:32,093: INFO: data_ingestion: Downloading data from https://drive.google.com/file/d/1vlhZ5c7abUKF8xXERIw6m9Te8fW7ohw3/view?usp=sharing into file artifacts/data_ingestion/data.zip]
[2024-03-01 15:51:00,190: INFO: data_ingestion: Downloaded data from https://drive.google.com/file/d/1vlhZ5c7abUKF8xXERIw6m9Te8fW7ohw3/view?usp=sharing into file artifacts/data_ingestion/data.zip]
[2024-03-01 15:51:01,400: INFO: main: >>>>>> stage Data Ingestion stage completed <<<<<<

x==========x]
[2024-03-01 15:58:43,177: INFO: common: yaml file: config\config.yaml loaded successfully]
[2024-03-01 15:58:43,186: INFO: common: yaml file: params.yaml loaded successfully]
[2024-03-01 15:58:43,188: INFO: common: created directory at: artifacts]
[2024-03-01 15:58:43,190: INFO: common: created directory at: artifacts/prepare_base_model]
[2024-03-01 15:58:44,091: WARNING: saving_utils: Compiled the loaded model, but the compiled metrics have yet to be built. `model.compile_metrics` will be empty until you train or evaluate the model.]
[2024-03-01 16:01:50,901: INFO: common: yaml file: config\config.yaml loaded successfully]
[2024-03-01 16:01:50,907: INFO: common: yaml file: params.yaml loaded successfully]
[2024-03-01 16:01:50,910: INFO: common: created directory at: artifacts]
[2024-03-01 16:01:50,912: INFO: common: created directory at: artifacts\training]
[2024-03-01 16:28:27,515: INFO: main: >>>>>> stage Data Ingestion stage started <<<<<<]
[2024-03-01 16:28:27,517: INFO: common: yaml file: config\config.yaml loaded successfully]
[2024-03-01 16:28:27,520: INFO: common: yaml file: params.yaml loaded successfully]
[2024-03-01 16:28:27,520: INFO: common: created directory at: artifacts]
[2024-03-01 16:28:27,522: INFO: common: created directory at: artifacts/data_ingestion]
[2024-03-01 16:28:27,523: INFO: data_ingestion: Downloading data from https://drive.google.com/file/d/1vlhZ5c7abUKF8xXERIw6m9Te8fW7ohw3/view?usp=sharing into file artifacts/data_ingestion/data.zip]
[2024-03-01 16:29:11,632: INFO: data_ingestion: Downloaded data from https://drive.google.com/file/d/1vlhZ5c7abUKF8xXERIw6m9Te8fW7ohw3/view?usp=sharing into file artifacts/data_ingestion/data.zip]
[2024-03-01 16:29:12,847: INFO: main: >>>>>> stage Data Ingestion stage completed <<<<<<

x==========x]
[2024-03-01 16:29:12,848: INFO: main: *******************]
[2024-03-01 16:29:12,849: INFO: main: >>>>>> stage Prepare base model started <<<<<<]
[2024-03-01 16:29:12,849: ERROR: main: name 'PrepareBaseModelTrainingPipeline' is not defined]
Traceback (most recent call last):
  File "main.py", line 22, in <module>
    prepare_base_model = PrepareBaseModelTrainingPipeline()
NameError: name 'PrepareBaseModelTrainingPipeline' is not defined
[2024-03-01 16:55:01,283: INFO: main: >>>>>> stage Data Ingestion stage started <<<<<<]
[2024-03-01 16:55:01,287: INFO: common: yaml file: config\config.yaml loaded successfully]
[2024-03-01 16:55:01,291: INFO: common: yaml file: params.yaml loaded successfully]
[2024-03-01 16:55:01,293: INFO: common: created directory at: artifacts]
[2024-03-01 16:55:01,294: INFO: common: created directory at: artifacts/data_ingestion]
[2024-03-01 16:55:01,296: INFO: data_ingestion: Downloading data from https://drive.google.com/file/d/1vlhZ5c7abUKF8xXERIw6m9Te8fW7ohw3/view?usp=sharing into file artifacts/data_ingestion/data.zip]
[2024-03-01 16:56:15,579: INFO: data_ingestion: Downloaded data from https://drive.google.com/file/d/1vlhZ5c7abUKF8xXERIw6m9Te8fW7ohw3/view?usp=sharing into file artifacts/data_ingestion/data.zip]
[2024-03-01 16:56:16,639: INFO: main: >>>>>> stage Data Ingestion stage completed <<<<<<

x==========x]
[2024-03-01 16:56:16,640: INFO: main: *******************]
[2024-03-01 16:56:16,640: INFO: main: >>>>>> stage Prepare base model started <<<<<<]
[2024-03-01 16:56:16,643: INFO: common: yaml file: config\config.yaml loaded successfully]
[2024-03-01 16:56:16,645: INFO: common: yaml file: params.yaml loaded successfully]
[2024-03-01 16:56:16,646: INFO: common: created directory at: artifacts]
[2024-03-01 16:56:16,647: INFO: common: created directory at: artifacts/prepare_base_model]
[2024-03-01 16:56:17,231: WARNING: saving_utils: Compiled the loaded model, but the compiled metrics have yet to be built. `model.compile_metrics` will be empty until you train or evaluate the model.]
[2024-03-01 16:56:18,182: INFO: main: >>>>>> stage Prepare base model completed <<<<<<

x==========x]
[2024-03-01 16:56:18,184: INFO: main: *******************]
[2024-03-01 16:56:18,185: INFO: main: >>>>>> stage Training started <<<<<<]
[2024-03-01 16:56:18,191: INFO: common: yaml file: config\config.yaml loaded successfully]
[2024-03-01 16:56:18,197: INFO: common: yaml file: params.yaml loaded successfully]
[2024-03-01 16:56:18,199: INFO: common: created directory at: artifacts]
[2024-03-01 16:56:18,201: INFO: common: created directory at: artifacts\training]
[2024-03-01 16:57:11,364: INFO: main: >>>>>> stage Training completed <<<<<<

x==========x]
[2024-03-01 19:48:34,333: INFO: main: >>>>>> stage Data Ingestion stage started <<<<<<]
[2024-03-01 19:48:34,339: INFO: common: yaml file: config\config.yaml loaded successfully]
[2024-03-01 19:48:34,351: INFO: common: yaml file: params.yaml loaded successfully]
[2024-03-01 19:48:34,354: INFO: common: created directory at: artifacts]
[2024-03-01 19:48:34,356: INFO: common: created directory at: artifacts/data_ingestion]
[2024-03-01 19:48:34,357: INFO: data_ingestion: Downloading data from https://drive.google.com/file/d/1vlhZ5c7abUKF8xXERIw6m9Te8fW7ohw3/view?usp=sharing into file artifacts/data_ingestion/data.zip]
[2024-03-01 19:49:32,442: INFO: data_ingestion: Downloaded data from https://drive.google.com/file/d/1vlhZ5c7abUKF8xXERIw6m9Te8fW7ohw3/view?usp=sharing into file artifacts/data_ingestion/data.zip]
[2024-03-01 19:49:33,843: INFO: main: >>>>>> stage Data Ingestion stage completed <<<<<<

x==========x]
[2024-03-01 19:49:33,844: INFO: main: *******************]
[2024-03-01 19:49:33,844: INFO: main: >>>>>> stage Prepare base model started <<<<<<]
[2024-03-01 19:49:33,846: INFO: common: yaml file: config\config.yaml loaded successfully]
[2024-03-01 19:49:33,848: INFO: common: yaml file: params.yaml loaded successfully]
[2024-03-01 19:49:33,848: INFO: common: created directory at: artifacts]
[2024-03-01 19:49:33,848: INFO: common: created directory at: artifacts/prepare_base_model]
[2024-03-01 19:49:34,687: WARNING: saving_utils: Compiled the loaded model, but the compiled metrics have yet to be built. `model.compile_metrics` will be empty until you train or evaluate the model.]
[2024-03-01 19:49:35,863: INFO: main: >>>>>> stage Prepare base model completed <<<<<<

x==========x]
[2024-03-01 19:49:35,864: INFO: main: *******************]
[2024-03-01 19:49:35,864: INFO: main: >>>>>> stage Training started <<<<<<]
[2024-03-01 19:49:35,875: INFO: common: yaml file: config\config.yaml loaded successfully]
[2024-03-01 19:49:35,880: INFO: common: yaml file: params.yaml loaded successfully]
[2024-03-01 19:49:35,882: INFO: common: created directory at: artifacts]
[2024-03-01 19:49:35,890: INFO: common: created directory at: artifacts\training]
[2024-03-01 19:50:32,188: INFO: main: >>>>>> stage Training completed <<<<<<

x==========x]
[2024-03-01 19:50:32,190: INFO: main: *******************]
[2024-03-01 19:50:32,191: INFO: main: >>>>>> stage Evaluation stage started <<<<<<]
[2024-03-01 19:50:32,192: ERROR: main: name 'EvaluationPipeline' is not defined]
Traceback (most recent call last):
  File "main.py", line 50, in <module>
    model_evalution = EvaluationPipeline()
NameError: name 'EvaluationPipeline' is not defined
[2024-03-01 20:02:02,992: INFO: main: >>>>>> stage Data Ingestion stage started <<<<<<]
[2024-03-01 20:02:02,997: INFO: common: yaml file: config\config.yaml loaded successfully]
[2024-03-01 20:02:03,005: INFO: common: yaml file: params.yaml loaded successfully]
[2024-03-01 20:02:03,007: INFO: common: created directory at: artifacts]
[2024-03-01 20:02:03,008: INFO: common: created directory at: artifacts/data_ingestion]
[2024-03-01 20:02:03,009: INFO: data_ingestion: Downloading data from https://drive.google.com/file/d/1vlhZ5c7abUKF8xXERIw6m9Te8fW7ohw3/view?usp=sharing into file artifacts/data_ingestion/data.zip]
[2024-03-01 20:02:44,136: INFO: data_ingestion: Downloaded data from https://drive.google.com/file/d/1vlhZ5c7abUKF8xXERIw6m9Te8fW7ohw3/view?usp=sharing into file artifacts/data_ingestion/data.zip]
[2024-03-01 20:02:45,202: INFO: main: >>>>>> stage Data Ingestion stage completed <<<<<<

x==========x]
[2024-03-01 20:02:45,203: INFO: main: *******************]
[2024-03-01 20:02:45,203: INFO: main: >>>>>> stage Prepare base model started <<<<<<]
[2024-03-01 20:02:45,206: INFO: common: yaml file: config\config.yaml loaded successfully]
[2024-03-01 20:02:45,209: INFO: common: yaml file: params.yaml loaded successfully]
[2024-03-01 20:02:45,213: INFO: common: created directory at: artifacts]
[2024-03-01 20:02:45,214: INFO: common: created directory at: artifacts/prepare_base_model]
[2024-03-01 20:02:46,172: WARNING: saving_utils: Compiled the loaded model, but the compiled metrics have yet to be built. `model.compile_metrics` will be empty until you train or evaluate the model.]
[2024-03-01 20:02:47,648: INFO: main: >>>>>> stage Prepare base model completed <<<<<<

x==========x]
[2024-03-01 20:02:47,650: INFO: main: *******************]
[2024-03-01 20:02:47,652: INFO: main: >>>>>> stage Training started <<<<<<]
[2024-03-01 20:02:47,658: INFO: common: yaml file: config\config.yaml loaded successfully]
[2024-03-01 20:02:47,664: INFO: common: yaml file: params.yaml loaded successfully]
[2024-03-01 20:02:47,666: INFO: common: created directory at: artifacts]
[2024-03-01 20:02:47,668: INFO: common: created directory at: artifacts\training]
[2024-03-01 20:03:46,741: INFO: main: >>>>>> stage Training completed <<<<<<

x==========x]
[2024-03-01 20:03:46,742: INFO: main: *******************]
[2024-03-01 20:03:46,742: INFO: main: >>>>>> stage Evaluation stage started <<<<<<]
[2024-03-01 20:03:46,749: INFO: common: yaml file: config\config.yaml loaded successfully]
[2024-03-01 20:03:46,808: INFO: common: yaml file: params.yaml loaded successfully]
[2024-03-01 20:03:46,831: INFO: common: created directory at: artifacts]
[2024-03-01 20:04:06,675: INFO: common: json file saved at: scores.json]
[2024-03-01 20:04:06,678: INFO: common: json file saved at: scores.json]
[2024-03-01 20:04:06,679: INFO: main: >>>>>> stage Evaluation stage completed <<<<<<

x==========x]
[2024-03-01 20:27:06,560: INFO: stage_01_data_ingestion: >>>>>> stage Data Ingestion stage started <<<<<<]
[2024-03-01 20:27:06,563: INFO: common: yaml file: config\config.yaml loaded successfully]
[2024-03-01 20:27:06,570: INFO: common: yaml file: params.yaml loaded successfully]
[2024-03-01 20:27:06,573: INFO: common: created directory at: artifacts]
[2024-03-01 20:27:06,574: INFO: common: created directory at: artifacts/data_ingestion]
[2024-03-01 20:27:06,575: INFO: data_ingestion: Downloading data from https://drive.google.com/file/d/1vlhZ5c7abUKF8xXERIw6m9Te8fW7ohw3/view?usp=sharing into file artifacts/data_ingestion/data.zip]
[2024-03-01 20:28:32,465: INFO: data_ingestion: Downloaded data from https://drive.google.com/file/d/1vlhZ5c7abUKF8xXERIw6m9Te8fW7ohw3/view?usp=sharing into file artifacts/data_ingestion/data.zip]
[2024-03-01 20:28:33,457: INFO: stage_01_data_ingestion: >>>>>> stage Data Ingestion stage completed <<<<<<

x==========x]
[2024-03-01 20:28:57,023: INFO: stage_02_prepare_base_model: *******************]
[2024-03-01 20:28:57,025: INFO: stage_02_prepare_base_model: >>>>>> stage Prepare base model started <<<<<<]
[2024-03-01 20:28:57,029: INFO: common: yaml file: config\config.yaml loaded successfully]
[2024-03-01 20:28:57,031: INFO: common: yaml file: params.yaml loaded successfully]
[2024-03-01 20:28:57,032: INFO: common: created directory at: artifacts]
[2024-03-01 20:28:57,033: INFO: common: created directory at: artifacts/prepare_base_model]
[2024-03-01 20:28:57,860: WARNING: saving_utils: Compiled the loaded model, but the compiled metrics have yet to be built. `model.compile_metrics` will be empty until you train or evaluate the model.]
[2024-03-01 20:28:58,744: INFO: stage_02_prepare_base_model: >>>>>> stage Prepare base model completed <<<<<<

x==========x]
[2024-03-01 20:29:09,899: INFO: stage_03_model_training: *******************]
[2024-03-01 20:29:09,899: INFO: stage_03_model_training: >>>>>> stage Training started <<<<<<]
[2024-03-01 20:29:09,906: INFO: common: yaml file: config\config.yaml loaded successfully]
[2024-03-01 20:29:09,910: INFO: common: yaml file: params.yaml loaded successfully]
[2024-03-01 20:29:09,911: INFO: common: created directory at: artifacts]
[2024-03-01 20:29:09,913: INFO: common: created directory at: artifacts\training]
[2024-03-01 20:30:13,311: INFO: stage_03_model_training: >>>>>> stage Training completed <<<<<<

x==========x]
[2024-03-01 20:30:32,176: INFO: stage_04_model_evaluation: *******************]
[2024-03-01 20:30:32,178: INFO: stage_04_model_evaluation: >>>>>> stage Evaluation stage started <<<<<<]
[2024-03-01 20:30:32,180: INFO: common: yaml file: config\config.yaml loaded successfully]
[2024-03-01 20:30:32,187: INFO: common: yaml file: params.yaml loaded successfully]
[2024-03-01 20:30:32,189: INFO: common: created directory at: artifacts]
[2024-03-01 20:30:51,269: INFO: common: json file saved at: scores.json]
[2024-03-01 20:30:51,271: INFO: common: json file saved at: scores.json]
[2024-03-01 20:30:51,272: INFO: stage_04_model_evaluation: >>>>>> stage Evaluation stage completed <<<<<<

x==========x]
[2024-03-01 20:42:55,333: INFO: _internal: [31m[1mWARNING: This is a development server. Do not use it in a production deployment. Use a production WSGI server instead.[0m
 * Running on all addresses (0.0.0.0)
 * Running on http://127.0.0.1:8080
 * Running on http://192.168.43.186:8080]
[2024-03-01 20:42:55,334: INFO: _internal: [33mPress CTRL+C to quit[0m]
[2024-03-01 20:43:16,690: INFO: _internal: 127.0.0.1 - - [01/Mar/2024 20:43:16] "GET / HTTP/1.1" 200 -]
[2024-03-01 20:44:16,312: ERROR: app: Exception on /predict [POST]]
Traceback (most recent call last):
  File "C:\Users\HP\anaconda3\envs\kdvenv\lib\site-packages\flask\app.py", line 2190, in wsgi_app
    response = self.full_dispatch_request()
  File "C:\Users\HP\anaconda3\envs\kdvenv\lib\site-packages\flask\app.py", line 1486, in full_dispatch_request
    rv = self.handle_user_exception(e)
  File "C:\Users\HP\anaconda3\envs\kdvenv\lib\site-packages\flask_cors\extension.py", line 176, in wrapped_function
    return cors_after_request(app.make_response(f(*args, **kwargs)))
  File "C:\Users\HP\anaconda3\envs\kdvenv\lib\site-packages\flask\app.py", line 1484, in full_dispatch_request
    rv = self.dispatch_request()
  File "C:\Users\HP\anaconda3\envs\kdvenv\lib\site-packages\flask\app.py", line 1469, in dispatch_request
    return self.ensure_sync(self.view_functions[rule.endpoint])(**view_args)
  File "C:\Users\HP\anaconda3\envs\kdvenv\lib\site-packages\flask_cors\decorator.py", line 130, in wrapped_function
    resp = make_response(f(*args, **kwargs))
  File "app.py", line 44, in predictRoute
    result = clApp.classifier.predict()
  File "e:\kidneydiseaseclassfication\src\cnnClassifier\pipeline\prediction.py", line 16, in predict
    model = load_model(os.path.join("model", "model.h5"))
  File "C:\Users\HP\anaconda3\envs\kdvenv\lib\site-packages\keras\saving\saving_api.py", line 212, in load_model
    return legacy_sm_saving_lib.load_model(
  File "C:\Users\HP\anaconda3\envs\kdvenv\lib\site-packages\keras\utils\traceback_utils.py", line 70, in error_handler
    raise e.with_traceback(filtered_tb) from None
  File "C:\Users\HP\anaconda3\envs\kdvenv\lib\site-packages\keras\saving\legacy\save.py", line 230, in load_model
    raise IOError(
OSError: No file or directory found at model\model.h5
[2024-03-01 20:44:16,336: INFO: _internal: 127.0.0.1 - - [01/Mar/2024 20:44:16] "[35m[1mPOST /predict HTTP/1.1[0m" 500 -]
[2024-03-01 20:45:52,261: INFO: _internal: [31m[1mWARNING: This is a development server. Do not use it in a production deployment. Use a production WSGI server instead.[0m
 * Running on all addresses (0.0.0.0)
 * Running on http://127.0.0.1:8080
 * Running on http://192.168.43.186:8080]
[2024-03-01 20:45:52,263: INFO: _internal: [33mPress CTRL+C to quit[0m]
[2024-03-01 20:46:09,373: INFO: _internal: 127.0.0.1 - - [01/Mar/2024 20:46:09] "GET / HTTP/1.1" 200 -]
[2024-03-01 20:46:33,738: ERROR: app: Exception on /predict [POST]]
Traceback (most recent call last):
  File "C:\Users\HP\anaconda3\envs\kdvenv\lib\site-packages\flask\app.py", line 2190, in wsgi_app
    response = self.full_dispatch_request()
  File "C:\Users\HP\anaconda3\envs\kdvenv\lib\site-packages\flask\app.py", line 1486, in full_dispatch_request
    rv = self.handle_user_exception(e)
  File "C:\Users\HP\anaconda3\envs\kdvenv\lib\site-packages\flask_cors\extension.py", line 176, in wrapped_function
    return cors_after_request(app.make_response(f(*args, **kwargs)))
  File "C:\Users\HP\anaconda3\envs\kdvenv\lib\site-packages\flask\app.py", line 1484, in full_dispatch_request
    rv = self.dispatch_request()
  File "C:\Users\HP\anaconda3\envs\kdvenv\lib\site-packages\flask\app.py", line 1469, in dispatch_request
    return self.ensure_sync(self.view_functions[rule.endpoint])(**view_args)
  File "C:\Users\HP\anaconda3\envs\kdvenv\lib\site-packages\flask_cors\decorator.py", line 130, in wrapped_function
    resp = make_response(f(*args, **kwargs))
  File "app.py", line 44, in predictRoute
    result = clApp.classifier.predict()
  File "e:\kidneydiseaseclassfication\src\cnnClassifier\pipeline\prediction.py", line 16, in predict
    model = load_model(os.path.join("model", "model.h5"))
  File "C:\Users\HP\anaconda3\envs\kdvenv\lib\site-packages\keras\saving\saving_api.py", line 212, in load_model
    return legacy_sm_saving_lib.load_model(
  File "C:\Users\HP\anaconda3\envs\kdvenv\lib\site-packages\keras\utils\traceback_utils.py", line 70, in error_handler
    raise e.with_traceback(filtered_tb) from None
  File "C:\Users\HP\anaconda3\envs\kdvenv\lib\site-packages\keras\saving\legacy\save.py", line 230, in load_model
    raise IOError(
OSError: No file or directory found at model\model.h5
[2024-03-01 20:46:33,744: INFO: _internal: 127.0.0.1 - - [01/Mar/2024 20:46:33] "[35m[1mPOST /predict HTTP/1.1[0m" 500 -]
[2024-03-01 20:50:08,196: INFO: _internal: 127.0.0.1 - - [01/Mar/2024 20:50:08] "GET / HTTP/1.1" 200 -]
[2024-03-01 20:50:15,038: ERROR: app: Exception on /predict [POST]]
Traceback (most recent call last):
  File "C:\Users\HP\anaconda3\envs\kdvenv\lib\site-packages\flask\app.py", line 2190, in wsgi_app
    response = self.full_dispatch_request()
  File "C:\Users\HP\anaconda3\envs\kdvenv\lib\site-packages\flask\app.py", line 1486, in full_dispatch_request
    rv = self.handle_user_exception(e)
  File "C:\Users\HP\anaconda3\envs\kdvenv\lib\site-packages\flask_cors\extension.py", line 176, in wrapped_function
    return cors_after_request(app.make_response(f(*args, **kwargs)))
  File "C:\Users\HP\anaconda3\envs\kdvenv\lib\site-packages\flask\app.py", line 1484, in full_dispatch_request
    rv = self.dispatch_request()
  File "C:\Users\HP\anaconda3\envs\kdvenv\lib\site-packages\flask\app.py", line 1469, in dispatch_request
    return self.ensure_sync(self.view_functions[rule.endpoint])(**view_args)
  File "C:\Users\HP\anaconda3\envs\kdvenv\lib\site-packages\flask_cors\decorator.py", line 130, in wrapped_function
    resp = make_response(f(*args, **kwargs))
  File "app.py", line 44, in predictRoute
    result = clApp.classifier.predict()
  File "e:\kidneydiseaseclassfication\src\cnnClassifier\pipeline\prediction.py", line 16, in predict
    model = load_model(os.path.join("model", "model.h5"))
  File "C:\Users\HP\anaconda3\envs\kdvenv\lib\site-packages\keras\saving\saving_api.py", line 212, in load_model
    return legacy_sm_saving_lib.load_model(
  File "C:\Users\HP\anaconda3\envs\kdvenv\lib\site-packages\keras\utils\traceback_utils.py", line 70, in error_handler
    raise e.with_traceback(filtered_tb) from None
  File "C:\Users\HP\anaconda3\envs\kdvenv\lib\site-packages\keras\saving\legacy\save.py", line 230, in load_model
    raise IOError(
OSError: No file or directory found at model\model.h5
[2024-03-01 20:50:15,043: INFO: _internal: 127.0.0.1 - - [01/Mar/2024 20:50:15] "[35m[1mPOST /predict HTTP/1.1[0m" 500 -]
[2024-03-01 20:53:07,038: INFO: _internal: 127.0.0.1 - - [01/Mar/2024 20:53:07] "GET / HTTP/1.1" 200 -]
[2024-03-01 20:53:14,726: ERROR: app: Exception on /predict [POST]]
Traceback (most recent call last):
  File "C:\Users\HP\anaconda3\envs\kdvenv\lib\site-packages\flask\app.py", line 2190, in wsgi_app
    response = self.full_dispatch_request()
  File "C:\Users\HP\anaconda3\envs\kdvenv\lib\site-packages\flask\app.py", line 1486, in full_dispatch_request
    rv = self.handle_user_exception(e)
  File "C:\Users\HP\anaconda3\envs\kdvenv\lib\site-packages\flask_cors\extension.py", line 176, in wrapped_function
    return cors_after_request(app.make_response(f(*args, **kwargs)))
  File "C:\Users\HP\anaconda3\envs\kdvenv\lib\site-packages\flask\app.py", line 1484, in full_dispatch_request
    rv = self.dispatch_request()
  File "C:\Users\HP\anaconda3\envs\kdvenv\lib\site-packages\flask\app.py", line 1469, in dispatch_request
    return self.ensure_sync(self.view_functions[rule.endpoint])(**view_args)
  File "C:\Users\HP\anaconda3\envs\kdvenv\lib\site-packages\flask_cors\decorator.py", line 130, in wrapped_function
    resp = make_response(f(*args, **kwargs))
  File "app.py", line 44, in predictRoute
    result = clApp.classifier.predict()
  File "e:\kidneydiseaseclassfication\src\cnnClassifier\pipeline\prediction.py", line 16, in predict
    model = load_model(os.path.join("model", "model.h5"))
  File "C:\Users\HP\anaconda3\envs\kdvenv\lib\site-packages\keras\saving\saving_api.py", line 212, in load_model
    return legacy_sm_saving_lib.load_model(
  File "C:\Users\HP\anaconda3\envs\kdvenv\lib\site-packages\keras\utils\traceback_utils.py", line 70, in error_handler
    raise e.with_traceback(filtered_tb) from None
  File "C:\Users\HP\anaconda3\envs\kdvenv\lib\site-packages\keras\saving\legacy\save.py", line 230, in load_model
    raise IOError(
OSError: No file or directory found at model\model.h5
[2024-03-01 20:53:14,731: INFO: _internal: 127.0.0.1 - - [01/Mar/2024 20:53:14] "[35m[1mPOST /predict HTTP/1.1[0m" 500 -]
[2024-03-01 21:03:34,903: INFO: _internal: [31m[1mWARNING: This is a development server. Do not use it in a production deployment. Use a production WSGI server instead.[0m
 * Running on all addresses (0.0.0.0)
 * Running on http://127.0.0.1:8080
 * Running on http://192.168.43.186:8080]
[2024-03-01 21:03:34,905: INFO: _internal: [33mPress CTRL+C to quit[0m]
[2024-03-01 21:03:46,377: INFO: _internal: 127.0.0.1 - - [01/Mar/2024 21:03:46] "GET / HTTP/1.1" 200 -]
[2024-03-01 21:03:52,197: ERROR: app: Exception on /predict [POST]]
Traceback (most recent call last):
  File "C:\Users\HP\anaconda3\envs\kdvenv\lib\site-packages\flask\app.py", line 2190, in wsgi_app
    response = self.full_dispatch_request()
  File "C:\Users\HP\anaconda3\envs\kdvenv\lib\site-packages\flask\app.py", line 1486, in full_dispatch_request
    rv = self.handle_user_exception(e)
  File "C:\Users\HP\anaconda3\envs\kdvenv\lib\site-packages\flask_cors\extension.py", line 176, in wrapped_function
    return cors_after_request(app.make_response(f(*args, **kwargs)))
  File "C:\Users\HP\anaconda3\envs\kdvenv\lib\site-packages\flask\app.py", line 1484, in full_dispatch_request
    rv = self.dispatch_request()
  File "C:\Users\HP\anaconda3\envs\kdvenv\lib\site-packages\flask\app.py", line 1469, in dispatch_request
    return self.ensure_sync(self.view_functions[rule.endpoint])(**view_args)
  File "C:\Users\HP\anaconda3\envs\kdvenv\lib\site-packages\flask_cors\decorator.py", line 130, in wrapped_function
    resp = make_response(f(*args, **kwargs))
  File "app.py", line 44, in predictRoute
    result = clApp.classifier.predict()
  File "e:\kidneydiseaseclassfication\src\cnnClassifier\pipeline\prediction.py", line 16, in predict
    model = load_model(os.path.join("model", "model.h5"))
  File "C:\Users\HP\anaconda3\envs\kdvenv\lib\site-packages\keras\saving\saving_api.py", line 212, in load_model
    return legacy_sm_saving_lib.load_model(
  File "C:\Users\HP\anaconda3\envs\kdvenv\lib\site-packages\keras\utils\traceback_utils.py", line 70, in error_handler
    raise e.with_traceback(filtered_tb) from None
  File "C:\Users\HP\anaconda3\envs\kdvenv\lib\site-packages\keras\saving\legacy\save.py", line 230, in load_model
    raise IOError(
OSError: No file or directory found at model\model.h5
[2024-03-01 21:03:52,219: INFO: _internal: 127.0.0.1 - - [01/Mar/2024 21:03:52] "[35m[1mPOST /predict HTTP/1.1[0m" 500 -]
[2024-03-01 21:05:27,075: INFO: _internal: [31m[1mWARNING: This is a development server. Do not use it in a production deployment. Use a production WSGI server instead.[0m
 * Running on all addresses (0.0.0.0)
 * Running on http://127.0.0.1:8080
 * Running on http://192.168.43.186:8080]
[2024-03-01 21:05:27,076: INFO: _internal: [33mPress CTRL+C to quit[0m]
[2024-03-01 21:05:40,264: INFO: _internal: 127.0.0.1 - - [01/Mar/2024 21:05:40] "GET / HTTP/1.1" 200 -]
[2024-03-01 21:05:49,442: ERROR: app: Exception on /predict [POST]]
Traceback (most recent call last):
  File "C:\Users\HP\anaconda3\envs\kdvenv\lib\site-packages\flask\app.py", line 2190, in wsgi_app
    response = self.full_dispatch_request()
  File "C:\Users\HP\anaconda3\envs\kdvenv\lib\site-packages\flask\app.py", line 1486, in full_dispatch_request
    rv = self.handle_user_exception(e)
  File "C:\Users\HP\anaconda3\envs\kdvenv\lib\site-packages\flask_cors\extension.py", line 176, in wrapped_function
    return cors_after_request(app.make_response(f(*args, **kwargs)))
  File "C:\Users\HP\anaconda3\envs\kdvenv\lib\site-packages\flask\app.py", line 1484, in full_dispatch_request
    rv = self.dispatch_request()
  File "C:\Users\HP\anaconda3\envs\kdvenv\lib\site-packages\flask\app.py", line 1469, in dispatch_request
    return self.ensure_sync(self.view_functions[rule.endpoint])(**view_args)
  File "C:\Users\HP\anaconda3\envs\kdvenv\lib\site-packages\flask_cors\decorator.py", line 130, in wrapped_function
    resp = make_response(f(*args, **kwargs))
  File "app.py", line 44, in predictRoute
    result = clApp.classifier.predict()
  File "e:\kidneydiseaseclassfication\src\cnnClassifier\pipeline\prediction.py", line 16, in predict
    model = load_model(os.path.join("model", "model.h5"))
  File "C:\Users\HP\anaconda3\envs\kdvenv\lib\site-packages\keras\saving\saving_api.py", line 212, in load_model
    return legacy_sm_saving_lib.load_model(
  File "C:\Users\HP\anaconda3\envs\kdvenv\lib\site-packages\keras\utils\traceback_utils.py", line 70, in error_handler
    raise e.with_traceback(filtered_tb) from None
  File "C:\Users\HP\anaconda3\envs\kdvenv\lib\site-packages\keras\saving\legacy\save.py", line 230, in load_model
    raise IOError(
OSError: No file or directory found at model\model.h5
[2024-03-01 21:05:49,461: INFO: _internal: 127.0.0.1 - - [01/Mar/2024 21:05:49] "[35m[1mPOST /predict HTTP/1.1[0m" 500 -]
[2024-03-04 18:22:36,147: INFO: _internal: [31m[1mWARNING: This is a development server. Do not use it in a production deployment. Use a production WSGI server instead.[0m
 * Running on all addresses (0.0.0.0)
 * Running on http://127.0.0.1:8080
 * Running on http://192.168.43.186:8080]
[2024-03-04 18:22:36,148: INFO: _internal: [33mPress CTRL+C to quit[0m]
[2024-03-04 18:22:44,271: INFO: _internal: 127.0.0.1 - - [04/Mar/2024 18:22:44] "GET / HTTP/1.1" 200 -]
[2024-03-04 18:23:03,517: ERROR: app: Exception on /predict [POST]]
Traceback (most recent call last):
  File "C:\Users\HP\anaconda3\envs\kdvenv\lib\site-packages\flask\app.py", line 2190, in wsgi_app
    response = self.full_dispatch_request()
  File "C:\Users\HP\anaconda3\envs\kdvenv\lib\site-packages\flask\app.py", line 1486, in full_dispatch_request
    rv = self.handle_user_exception(e)
  File "C:\Users\HP\anaconda3\envs\kdvenv\lib\site-packages\flask_cors\extension.py", line 176, in wrapped_function
    return cors_after_request(app.make_response(f(*args, **kwargs)))
  File "C:\Users\HP\anaconda3\envs\kdvenv\lib\site-packages\flask\app.py", line 1484, in full_dispatch_request
    rv = self.dispatch_request()
  File "C:\Users\HP\anaconda3\envs\kdvenv\lib\site-packages\flask\app.py", line 1469, in dispatch_request
    return self.ensure_sync(self.view_functions[rule.endpoint])(**view_args)
  File "C:\Users\HP\anaconda3\envs\kdvenv\lib\site-packages\flask_cors\decorator.py", line 130, in wrapped_function
    resp = make_response(f(*args, **kwargs))
  File "app.py", line 44, in predictRoute
    result = clApp.classifier.predict()
  File "e:\kidneydiseaseclassfication\src\cnnClassifier\pipeline\prediction.py", line 16, in predict
    model = load_model(os.path.join("model", "model.h5"))
  File "C:\Users\HP\anaconda3\envs\kdvenv\lib\site-packages\keras\saving\saving_api.py", line 212, in load_model
    return legacy_sm_saving_lib.load_model(
  File "C:\Users\HP\anaconda3\envs\kdvenv\lib\site-packages\keras\utils\traceback_utils.py", line 70, in error_handler
    raise e.with_traceback(filtered_tb) from None
  File "C:\Users\HP\anaconda3\envs\kdvenv\lib\site-packages\keras\saving\legacy\save.py", line 230, in load_model
    raise IOError(
OSError: No file or directory found at model\model.h5
[2024-03-04 18:23:03,552: INFO: _internal: 127.0.0.1 - - [04/Mar/2024 18:23:03] "[35m[1mPOST /predict HTTP/1.1[0m" 500 -]
[2024-03-04 18:33:20,212: INFO: main: >>>>>> stage Data Ingestion stage started <<<<<<]
[2024-03-04 18:33:20,215: INFO: common: yaml file: config\config.yaml loaded successfully]
[2024-03-04 18:33:20,232: INFO: common: yaml file: params.yaml loaded successfully]
[2024-03-04 18:33:20,235: INFO: common: created directory at: artifacts]
[2024-03-04 18:33:20,237: INFO: common: created directory at: artifacts/data_ingestion]
[2024-03-04 18:33:20,237: INFO: data_ingestion: Downloading data from https://drive.google.com/file/d/1vlhZ5c7abUKF8xXERIw6m9Te8fW7ohw3/view?usp=sharing into file artifacts/data_ingestion/data.zip]
[2024-03-04 18:35:06,972: INFO: data_ingestion: Downloaded data from https://drive.google.com/file/d/1vlhZ5c7abUKF8xXERIw6m9Te8fW7ohw3/view?usp=sharing into file artifacts/data_ingestion/data.zip]
[2024-03-04 18:35:08,751: INFO: main: >>>>>> stage Data Ingestion stage completed <<<<<<

x==========x]
[2024-03-04 18:35:08,752: INFO: main: *******************]
[2024-03-04 18:35:08,753: INFO: main: >>>>>> stage Prepare base model started <<<<<<]
[2024-03-04 18:35:08,760: INFO: common: yaml file: config\config.yaml loaded successfully]
[2024-03-04 18:35:08,768: INFO: common: yaml file: params.yaml loaded successfully]
[2024-03-04 18:35:08,768: INFO: common: created directory at: artifacts]
[2024-03-04 18:35:08,770: INFO: common: created directory at: artifacts/prepare_base_model]
[2024-03-04 18:35:09,901: WARNING: saving_utils: Compiled the loaded model, but the compiled metrics have yet to be built. `model.compile_metrics` will be empty until you train or evaluate the model.]
[2024-03-04 18:35:10,995: INFO: main: >>>>>> stage Prepare base model completed <<<<<<

x==========x]
[2024-03-04 18:35:10,997: INFO: main: *******************]
[2024-03-04 18:35:10,997: INFO: main: >>>>>> stage Training started <<<<<<]
[2024-03-04 18:35:11,003: INFO: common: yaml file: config\config.yaml loaded successfully]
[2024-03-04 18:35:11,010: INFO: common: yaml file: params.yaml loaded successfully]
[2024-03-04 18:35:11,012: INFO: common: created directory at: artifacts]
[2024-03-04 18:35:11,014: INFO: common: created directory at: artifacts\training]
[2024-03-04 18:36:17,831: INFO: main: >>>>>> stage Training completed <<<<<<

x==========x]
[2024-03-04 18:36:17,833: INFO: main: *******************]
[2024-03-04 18:36:17,833: INFO: main: >>>>>> stage Evaluation stage started <<<<<<]
[2024-03-04 18:36:17,838: INFO: common: yaml file: config\config.yaml loaded successfully]
[2024-03-04 18:36:17,840: INFO: common: yaml file: params.yaml loaded successfully]
[2024-03-04 18:36:17,841: INFO: common: created directory at: artifacts]
[2024-03-04 18:36:17,899: ERROR: main: No file or directory found at E:/KidneyDiseaseclassfication/artifacts/training/model.h5]
Traceback (most recent call last):
  File "main.py", line 52, in <module>
    model_evalution.main()
  File "e:\kidneydiseaseclassfication\src\cnnClassifier\pipeline\stage_04_model_evaluation.py", line 18, in main
    evaluation.evaluation()
  File "e:\kidneydiseaseclassfication\src\cnnClassifier\components\model_evaluation_mlflow.py", line 46, in evaluation
    self.model = self.load_model(self.config.path_of_model)
  File "e:\kidneydiseaseclassfication\src\cnnClassifier\components\model_evaluation_mlflow.py", line 42, in load_model
    return tf.keras.models.load_model(path)
  File "C:\Users\HP\anaconda3\envs\kdvenv\lib\site-packages\keras\saving\saving_api.py", line 212, in load_model
    return legacy_sm_saving_lib.load_model(
  File "C:\Users\HP\anaconda3\envs\kdvenv\lib\site-packages\keras\utils\traceback_utils.py", line 70, in error_handler
    raise e.with_traceback(filtered_tb) from None
  File "C:\Users\HP\anaconda3\envs\kdvenv\lib\site-packages\keras\saving\legacy\save.py", line 230, in load_model
    raise IOError(
OSError: No file or directory found at E:/KidneyDiseaseclassfication/artifacts/training/model.h5
[2024-03-04 18:38:13,735: INFO: common: yaml file: E:\KidneyDiseaseclassfication\config\config.yaml loaded successfully]
[2024-03-04 18:38:13,741: INFO: common: yaml file: E:\KidneyDiseaseclassfication\params.yaml loaded successfully]
[2024-03-04 18:38:23,188: INFO: common: yaml file: E:\KidneyDiseaseclassfication\config\config.yaml loaded successfully]
[2024-03-04 18:38:23,193: INFO: common: yaml file: E:\KidneyDiseaseclassfication\params.yaml loaded successfully]
[2024-03-04 18:40:00,767: INFO: common: yaml file: E:\KidneyDiseaseclassfication\config\config.yaml loaded successfully]
[2024-03-04 18:40:00,775: INFO: common: yaml file: E:\KidneyDiseaseclassfication\params.yaml loaded successfully]
[2024-03-04 18:44:43,119: INFO: main: >>>>>> stage Data Ingestion stage started <<<<<<]
[2024-03-04 18:44:43,121: INFO: common: yaml file: config\config.yaml loaded successfully]
[2024-03-04 18:44:43,123: INFO: common: yaml file: params.yaml loaded successfully]
[2024-03-04 18:44:43,124: INFO: common: created directory at: artifacts]
[2024-03-04 18:44:43,125: INFO: common: created directory at: artifacts/data_ingestion]
[2024-03-04 18:44:43,126: INFO: data_ingestion: Downloading data from https://drive.google.com/file/d/1vlhZ5c7abUKF8xXERIw6m9Te8fW7ohw3/view?usp=sharing into file artifacts/data_ingestion/data.zip]
[2024-03-04 18:46:18,837: INFO: data_ingestion: Downloaded data from https://drive.google.com/file/d/1vlhZ5c7abUKF8xXERIw6m9Te8fW7ohw3/view?usp=sharing into file artifacts/data_ingestion/data.zip]
[2024-03-04 18:46:19,964: INFO: main: >>>>>> stage Data Ingestion stage completed <<<<<<

x==========x]
[2024-03-04 18:46:19,965: INFO: main: *******************]
[2024-03-04 18:46:19,966: INFO: main: >>>>>> stage Prepare base model started <<<<<<]
[2024-03-04 18:46:19,969: INFO: common: yaml file: config\config.yaml loaded successfully]
[2024-03-04 18:46:19,976: INFO: common: yaml file: params.yaml loaded successfully]
[2024-03-04 18:46:19,978: INFO: common: created directory at: artifacts]
[2024-03-04 18:46:19,980: INFO: common: created directory at: artifacts/prepare_base_model]
[2024-03-04 18:46:20,567: WARNING: saving_utils: Compiled the loaded model, but the compiled metrics have yet to be built. `model.compile_metrics` will be empty until you train or evaluate the model.]
[2024-03-04 18:46:21,351: INFO: main: >>>>>> stage Prepare base model completed <<<<<<

x==========x]
[2024-03-04 18:46:21,353: INFO: main: *******************]
[2024-03-04 18:46:21,353: INFO: main: >>>>>> stage Training started <<<<<<]
[2024-03-04 18:46:21,355: INFO: common: yaml file: config\config.yaml loaded successfully]
[2024-03-04 18:46:21,360: INFO: common: yaml file: params.yaml loaded successfully]
[2024-03-04 18:46:21,362: INFO: common: created directory at: artifacts]
[2024-03-04 18:46:21,368: INFO: common: created directory at: artifacts\training]
[2024-03-04 18:47:15,222: INFO: main: >>>>>> stage Training completed <<<<<<

x==========x]
[2024-03-04 19:06:46,070: INFO: common: yaml file: E:\KidneyDiseaseclassfication\config\config.yaml loaded successfully]
[2024-03-04 19:06:46,092: INFO: common: yaml file: E:\KidneyDiseaseclassfication\params.yaml loaded successfully]
[2024-03-04 19:07:06,867: INFO: common: json file saved at: E:\KidneyDiseaseclassfication\scores.json]
[2024-03-04 19:07:14,046: WARNING: save: Found untraced functions such as _jit_compiled_convolution_op, _jit_compiled_convolution_op, _jit_compiled_convolution_op, _jit_compiled_convolution_op, _jit_compiled_convolution_op while saving (showing 5 of 14). These functions will not be directly callable after loading.]
[2024-03-04 19:07:15,571: INFO: builder_impl: Assets written to: C:\Users\HP\AppData\Local\Temp\tmpnho0wpn3\model\data\model\assets]
[2024-03-04 19:12:49,473: INFO: _internal: [31m[1mWARNING: This is a development server. Do not use it in a production deployment. Use a production WSGI server instead.[0m
 * Running on all addresses (0.0.0.0)
 * Running on http://127.0.0.1:8080
 * Running on http://192.168.43.186:8080]
[2024-03-04 19:12:49,473: INFO: _internal: [33mPress CTRL+C to quit[0m]
[2024-03-04 19:13:02,079: INFO: _internal: 127.0.0.1 - - [04/Mar/2024 19:13:02] "GET / HTTP/1.1" 200 -]
[2024-03-04 19:13:10,759: ERROR: app: Exception on /predict [POST]]
Traceback (most recent call last):
  File "C:\Users\HP\anaconda3\envs\kdvenv\lib\site-packages\flask\app.py", line 2190, in wsgi_app
    response = self.full_dispatch_request()
  File "C:\Users\HP\anaconda3\envs\kdvenv\lib\site-packages\flask\app.py", line 1486, in full_dispatch_request
    rv = self.handle_user_exception(e)
  File "C:\Users\HP\anaconda3\envs\kdvenv\lib\site-packages\flask_cors\extension.py", line 176, in wrapped_function
    return cors_after_request(app.make_response(f(*args, **kwargs)))
  File "C:\Users\HP\anaconda3\envs\kdvenv\lib\site-packages\flask\app.py", line 1484, in full_dispatch_request
    rv = self.dispatch_request()
  File "C:\Users\HP\anaconda3\envs\kdvenv\lib\site-packages\flask\app.py", line 1469, in dispatch_request
    return self.ensure_sync(self.view_functions[rule.endpoint])(**view_args)
  File "C:\Users\HP\anaconda3\envs\kdvenv\lib\site-packages\flask_cors\decorator.py", line 130, in wrapped_function
    resp = make_response(f(*args, **kwargs))
  File "app.py", line 44, in predictRoute
    result = clApp.classifier.predict()
  File "e:\kidneydiseaseclassfication\src\cnnClassifier\pipeline\prediction.py", line 16, in predict
    model = load_model(os.path.join("model", "model.h5"))
  File "C:\Users\HP\anaconda3\envs\kdvenv\lib\site-packages\keras\saving\saving_api.py", line 212, in load_model
    return legacy_sm_saving_lib.load_model(
  File "C:\Users\HP\anaconda3\envs\kdvenv\lib\site-packages\keras\utils\traceback_utils.py", line 70, in error_handler
    raise e.with_traceback(filtered_tb) from None
  File "C:\Users\HP\anaconda3\envs\kdvenv\lib\site-packages\keras\saving\legacy\save.py", line 230, in load_model
    raise IOError(
OSError: No file or directory found at model\model.h5
[2024-03-04 19:13:10,797: INFO: _internal: 127.0.0.1 - - [04/Mar/2024 19:13:10] "[35m[1mPOST /predict HTTP/1.1[0m" 500 -]
[2024-03-04 19:15:55,105: INFO: _internal: [31m[1mWARNING: This is a development server. Do not use it in a production deployment. Use a production WSGI server instead.[0m
 * Running on all addresses (0.0.0.0)
 * Running on http://127.0.0.1:8080
 * Running on http://192.168.43.186:8080]
[2024-03-04 19:15:55,106: INFO: _internal: [33mPress CTRL+C to quit[0m]
[2024-03-04 19:19:09,709: INFO: _internal: 127.0.0.1 - - [04/Mar/2024 19:19:09] "GET / HTTP/1.1" 200 -]
[2024-03-04 19:19:11,776: INFO: _internal: 127.0.0.1 - - [04/Mar/2024 19:19:11] "[31m[1mPOST /predict HTTP/1.1[0m" 400 -]
[2024-03-04 19:19:17,809: INFO: _internal: 127.0.0.1 - - [04/Mar/2024 19:19:17] "GET / HTTP/1.1" 200 -]
[2024-03-04 19:19:27,128: ERROR: app: Exception on /predict [POST]]
Traceback (most recent call last):
  File "C:\Users\HP\anaconda3\envs\kdvenv\lib\site-packages\flask\app.py", line 2190, in wsgi_app
    response = self.full_dispatch_request()
  File "C:\Users\HP\anaconda3\envs\kdvenv\lib\site-packages\flask\app.py", line 1486, in full_dispatch_request
    rv = self.handle_user_exception(e)
  File "C:\Users\HP\anaconda3\envs\kdvenv\lib\site-packages\flask_cors\extension.py", line 176, in wrapped_function
    return cors_after_request(app.make_response(f(*args, **kwargs)))
  File "C:\Users\HP\anaconda3\envs\kdvenv\lib\site-packages\flask\app.py", line 1484, in full_dispatch_request
    rv = self.dispatch_request()
  File "C:\Users\HP\anaconda3\envs\kdvenv\lib\site-packages\flask\app.py", line 1469, in dispatch_request
    return self.ensure_sync(self.view_functions[rule.endpoint])(**view_args)
  File "C:\Users\HP\anaconda3\envs\kdvenv\lib\site-packages\flask_cors\decorator.py", line 130, in wrapped_function
    resp = make_response(f(*args, **kwargs))
  File "app.py", line 34, in predictRoute
    result = clApp.classifier.predict()
  File "e:\kidneydiseaseclassfication\src\cnnClassifier\pipeline\prediction.py", line 16, in predict
    model = load_model(os.path.join("model", "model.h5"))
  File "C:\Users\HP\anaconda3\envs\kdvenv\lib\site-packages\keras\saving\saving_api.py", line 212, in load_model
    return legacy_sm_saving_lib.load_model(
  File "C:\Users\HP\anaconda3\envs\kdvenv\lib\site-packages\keras\utils\traceback_utils.py", line 70, in error_handler
    raise e.with_traceback(filtered_tb) from None
  File "C:\Users\HP\anaconda3\envs\kdvenv\lib\site-packages\keras\saving\legacy\save.py", line 230, in load_model
    raise IOError(
OSError: No file or directory found at model\model.h5
[2024-03-04 19:19:27,153: INFO: _internal: 127.0.0.1 - - [04/Mar/2024 19:19:27] "[35m[1mPOST /predict HTTP/1.1[0m" 500 -]
[2024-03-04 19:26:56,181: INFO: _internal: [31m[1mWARNING: This is a development server. Do not use it in a production deployment. Use a production WSGI server instead.[0m
 * Running on all addresses (0.0.0.0)
 * Running on http://127.0.0.1:8080
 * Running on http://192.168.43.186:8080]
[2024-03-04 19:26:56,184: INFO: _internal: [33mPress CTRL+C to quit[0m]
[2024-03-04 19:27:29,367: INFO: _internal: 127.0.0.1 - - [04/Mar/2024 19:27:29] "GET / HTTP/1.1" 200 -]
[2024-03-04 19:27:39,629: ERROR: app: Exception on /predict [POST]]
Traceback (most recent call last):
  File "C:\Users\HP\anaconda3\envs\kdvenv\lib\site-packages\flask\app.py", line 2190, in wsgi_app
    response = self.full_dispatch_request()
  File "C:\Users\HP\anaconda3\envs\kdvenv\lib\site-packages\flask\app.py", line 1486, in full_dispatch_request
    rv = self.handle_user_exception(e)
  File "C:\Users\HP\anaconda3\envs\kdvenv\lib\site-packages\flask_cors\extension.py", line 176, in wrapped_function
    return cors_after_request(app.make_response(f(*args, **kwargs)))
  File "C:\Users\HP\anaconda3\envs\kdvenv\lib\site-packages\flask\app.py", line 1484, in full_dispatch_request
    rv = self.dispatch_request()
  File "C:\Users\HP\anaconda3\envs\kdvenv\lib\site-packages\flask\app.py", line 1469, in dispatch_request
    return self.ensure_sync(self.view_functions[rule.endpoint])(**view_args)
  File "C:\Users\HP\anaconda3\envs\kdvenv\lib\site-packages\flask_cors\decorator.py", line 130, in wrapped_function
    resp = make_response(f(*args, **kwargs))
  File "app.py", line 34, in predictRoute
    result = clApp.classifier.predict()
  File "e:\kidneydiseaseclassfication\src\cnnClassifier\pipeline\prediction.py", line 16, in predict
    model = load_model(os.path.join("model", "model.h5"))
  File "C:\Users\HP\anaconda3\envs\kdvenv\lib\site-packages\keras\saving\saving_api.py", line 212, in load_model
    return legacy_sm_saving_lib.load_model(
  File "C:\Users\HP\anaconda3\envs\kdvenv\lib\site-packages\keras\utils\traceback_utils.py", line 70, in error_handler
    raise e.with_traceback(filtered_tb) from None
  File "C:\Users\HP\anaconda3\envs\kdvenv\lib\site-packages\keras\saving\legacy\save.py", line 230, in load_model
    raise IOError(
OSError: No file or directory found at model\model.h5
[2024-03-04 19:27:39,646: INFO: _internal: 127.0.0.1 - - [04/Mar/2024 19:27:39] "[35m[1mPOST /predict HTTP/1.1[0m" 500 -]
[2024-03-04 19:27:48,791: INFO: _internal: 127.0.0.1 - - [04/Mar/2024 19:27:48] "GET / HTTP/1.1" 200 -]
[2024-03-04 19:27:58,999: ERROR: app: Exception on /predict [POST]]
Traceback (most recent call last):
  File "C:\Users\HP\anaconda3\envs\kdvenv\lib\site-packages\flask\app.py", line 2190, in wsgi_app
    response = self.full_dispatch_request()
  File "C:\Users\HP\anaconda3\envs\kdvenv\lib\site-packages\flask\app.py", line 1486, in full_dispatch_request
    rv = self.handle_user_exception(e)
  File "C:\Users\HP\anaconda3\envs\kdvenv\lib\site-packages\flask_cors\extension.py", line 176, in wrapped_function
    return cors_after_request(app.make_response(f(*args, **kwargs)))
  File "C:\Users\HP\anaconda3\envs\kdvenv\lib\site-packages\flask\app.py", line 1484, in full_dispatch_request
    rv = self.dispatch_request()
  File "C:\Users\HP\anaconda3\envs\kdvenv\lib\site-packages\flask\app.py", line 1469, in dispatch_request
    return self.ensure_sync(self.view_functions[rule.endpoint])(**view_args)
  File "C:\Users\HP\anaconda3\envs\kdvenv\lib\site-packages\flask_cors\decorator.py", line 130, in wrapped_function
    resp = make_response(f(*args, **kwargs))
  File "app.py", line 34, in predictRoute
    result = clApp.classifier.predict()
  File "e:\kidneydiseaseclassfication\src\cnnClassifier\pipeline\prediction.py", line 16, in predict
    model = load_model(os.path.join("model", "model.h5"))
  File "C:\Users\HP\anaconda3\envs\kdvenv\lib\site-packages\keras\saving\saving_api.py", line 212, in load_model
    return legacy_sm_saving_lib.load_model(
  File "C:\Users\HP\anaconda3\envs\kdvenv\lib\site-packages\keras\utils\traceback_utils.py", line 70, in error_handler
    raise e.with_traceback(filtered_tb) from None
  File "C:\Users\HP\anaconda3\envs\kdvenv\lib\site-packages\keras\saving\legacy\save.py", line 230, in load_model
    raise IOError(
OSError: No file or directory found at model\model.h5
[2024-03-04 19:27:59,004: INFO: _internal: 127.0.0.1 - - [04/Mar/2024 19:27:59] "[35m[1mPOST /predict HTTP/1.1[0m" 500 -]
[2024-03-04 19:36:25,022: INFO: _internal: [31m[1mWARNING: This is a development server. Do not use it in a production deployment. Use a production WSGI server instead.[0m
 * Running on all addresses (0.0.0.0)
 * Running on http://127.0.0.1:8080
 * Running on http://192.168.43.186:8080]
[2024-03-04 19:36:25,025: INFO: _internal: [33mPress CTRL+C to quit[0m]
[2024-03-04 19:36:45,866: INFO: _internal: 127.0.0.1 - - [04/Mar/2024 19:36:45] "GET / HTTP/1.1" 200 -]
[2024-03-04 19:37:06,924: ERROR: app: Exception on /predict [POST]]
Traceback (most recent call last):
  File "C:\Users\HP\anaconda3\envs\kdvenv\lib\site-packages\flask\app.py", line 2190, in wsgi_app
    response = self.full_dispatch_request()
  File "C:\Users\HP\anaconda3\envs\kdvenv\lib\site-packages\flask\app.py", line 1486, in full_dispatch_request
    rv = self.handle_user_exception(e)
  File "C:\Users\HP\anaconda3\envs\kdvenv\lib\site-packages\flask_cors\extension.py", line 176, in wrapped_function
    return cors_after_request(app.make_response(f(*args, **kwargs)))
  File "C:\Users\HP\anaconda3\envs\kdvenv\lib\site-packages\flask\app.py", line 1484, in full_dispatch_request
    rv = self.dispatch_request()
  File "C:\Users\HP\anaconda3\envs\kdvenv\lib\site-packages\flask\app.py", line 1469, in dispatch_request
    return self.ensure_sync(self.view_functions[rule.endpoint])(**view_args)
  File "C:\Users\HP\anaconda3\envs\kdvenv\lib\site-packages\flask_cors\decorator.py", line 130, in wrapped_function
    resp = make_response(f(*args, **kwargs))
  File "app.py", line 44, in predictRoute
    result = clApp.classifier.predict()
  File "e:\kidneydiseaseclassfication\src\cnnClassifier\pipeline\prediction.py", line 16, in predict
    model = load_model(os.path.join("model", "model.h5"))
  File "C:\Users\HP\anaconda3\envs\kdvenv\lib\site-packages\keras\saving\saving_api.py", line 212, in load_model
    return legacy_sm_saving_lib.load_model(
  File "C:\Users\HP\anaconda3\envs\kdvenv\lib\site-packages\keras\utils\traceback_utils.py", line 70, in error_handler
    raise e.with_traceback(filtered_tb) from None
  File "C:\Users\HP\anaconda3\envs\kdvenv\lib\site-packages\keras\saving\legacy\save.py", line 230, in load_model
    raise IOError(
OSError: No file or directory found at model\model.h5
[2024-03-04 19:37:06,939: INFO: _internal: 127.0.0.1 - - [04/Mar/2024 19:37:06] "[35m[1mPOST /predict HTTP/1.1[0m" 500 -]
[2024-03-04 19:39:36,384: INFO: _internal: [31m[1mWARNING: This is a development server. Do not use it in a production deployment. Use a production WSGI server instead.[0m
 * Running on all addresses (0.0.0.0)
 * Running on http://127.0.0.1:8080
 * Running on http://192.168.43.186:8080]
[2024-03-04 19:39:36,385: INFO: _internal: [33mPress CTRL+C to quit[0m]
[2024-03-04 19:40:19,316: INFO: _internal: 127.0.0.1 - - [04/Mar/2024 19:40:19] "GET / HTTP/1.1" 200 -]
[2024-03-04 19:40:24,246: ERROR: app: Exception on /predict [POST]]
Traceback (most recent call last):
  File "C:\Users\HP\anaconda3\envs\kdvenv\lib\site-packages\flask\app.py", line 2190, in wsgi_app
    response = self.full_dispatch_request()
  File "C:\Users\HP\anaconda3\envs\kdvenv\lib\site-packages\flask\app.py", line 1486, in full_dispatch_request
    rv = self.handle_user_exception(e)
  File "C:\Users\HP\anaconda3\envs\kdvenv\lib\site-packages\flask_cors\extension.py", line 176, in wrapped_function
    return cors_after_request(app.make_response(f(*args, **kwargs)))
  File "C:\Users\HP\anaconda3\envs\kdvenv\lib\site-packages\flask\app.py", line 1484, in full_dispatch_request
    rv = self.dispatch_request()
  File "C:\Users\HP\anaconda3\envs\kdvenv\lib\site-packages\flask\app.py", line 1469, in dispatch_request
    return self.ensure_sync(self.view_functions[rule.endpoint])(**view_args)
  File "C:\Users\HP\anaconda3\envs\kdvenv\lib\site-packages\flask_cors\decorator.py", line 130, in wrapped_function
    resp = make_response(f(*args, **kwargs))
  File "app.py", line 52, in predictRoute
    result = clApp.classifier.predict()
  File "e:\kidneydiseaseclassfication\src\cnnClassifier\pipeline\prediction.py", line 16, in predict
    model = load_model(os.path.join("model", "model.h5"))
  File "C:\Users\HP\anaconda3\envs\kdvenv\lib\site-packages\keras\saving\saving_api.py", line 212, in load_model
    return legacy_sm_saving_lib.load_model(
  File "C:\Users\HP\anaconda3\envs\kdvenv\lib\site-packages\keras\utils\traceback_utils.py", line 70, in error_handler
    raise e.with_traceback(filtered_tb) from None
  File "C:\Users\HP\anaconda3\envs\kdvenv\lib\site-packages\keras\saving\legacy\save.py", line 230, in load_model
    raise IOError(
OSError: No file or directory found at model\model.h5
[2024-03-04 19:40:24,270: INFO: _internal: 127.0.0.1 - - [04/Mar/2024 19:40:24] "[35m[1mPOST /predict HTTP/1.1[0m" 500 -]
[2024-03-05 09:41:26,814: INFO: common: yaml file: E:\KidneyDiseaseclassfication\config\config.yaml loaded successfully]
[2024-03-05 09:41:26,838: INFO: common: yaml file: E:\KidneyDiseaseclassfication\params.yaml loaded successfully]
[2024-03-05 09:41:26,843: INFO: common: created directory at: artifacts/data_ingestion]
[2024-03-05 09:41:26,845: INFO: 3172177572: Downloading data from https://drive.google.com/file/d/1vlhZ5c7abUKF8xXERIw6m9Te8fW7ohw3/view?usp=sharing into file artifacts/data_ingestion/data.zip]
[2024-03-05 09:42:09,748: INFO: 3172177572: Downloaded data from https://drive.google.com/file/d/1vlhZ5c7abUKF8xXERIw6m9Te8fW7ohw3/view?usp=sharing into file artifacts/data_ingestion/data.zip]
[2024-03-05 09:48:03,165: INFO: common: yaml file: config\config.yaml loaded successfully]
[2024-03-05 09:48:03,169: INFO: common: yaml file: params.yaml loaded successfully]
[2024-03-05 09:48:03,171: INFO: common: created directory at: artifacts]
[2024-03-05 09:48:03,174: INFO: common: created directory at: artifacts/prepare_base_model]
[2024-03-05 09:48:04,002: WARNING: saving_utils: Compiled the loaded model, but the compiled metrics have yet to be built. `model.compile_metrics` will be empty until you train or evaluate the model.]
[2024-03-05 09:50:50,096: INFO: common: yaml file: config\config.yaml loaded successfully]
[2024-03-05 09:50:50,104: INFO: common: yaml file: params.yaml loaded successfully]
[2024-03-05 09:50:50,107: INFO: common: created directory at: artifacts]
[2024-03-05 09:50:50,112: INFO: common: created directory at: artifacts\training]
[2024-03-05 10:34:16,790: INFO: common: yaml file: E:\KidneyDiseaseclassfication\config\config.yaml loaded successfully]
[2024-03-05 10:34:16,796: INFO: common: yaml file: E:\KidneyDiseaseclassfication\params.yaml loaded successfully]
[2024-03-05 10:35:33,421: INFO: common: yaml file: E:\KidneyDiseaseclassfication\config\config.yaml loaded successfully]
[2024-03-05 10:35:33,427: INFO: common: yaml file: E:\KidneyDiseaseclassfication\params.yaml loaded successfully]
[2024-03-05 10:36:37,572: INFO: common: yaml file: E:\KidneyDiseaseclassfication\config\config.yaml loaded successfully]
[2024-03-05 10:36:37,580: INFO: common: yaml file: E:\KidneyDiseaseclassfication\params.yaml loaded successfully]
[2024-03-05 10:38:00,259: INFO: common: yaml file: E:\KidneyDiseaseclassfication\config\config.yaml loaded successfully]
[2024-03-05 10:38:00,268: INFO: common: yaml file: E:\KidneyDiseaseclassfication\params.yaml loaded successfully]
[2024-03-05 10:38:18,721: INFO: common: json file saved at: E:\KidneyDiseaseclassfication\scores.json]
[2024-03-05 10:38:25,467: WARNING: save: Found untraced functions such as _jit_compiled_convolution_op, _jit_compiled_convolution_op, _jit_compiled_convolution_op, _jit_compiled_convolution_op, _jit_compiled_convolution_op while saving (showing 5 of 14). These functions will not be directly callable after loading.]
[2024-03-05 10:38:26,838: INFO: builder_impl: Assets written to: C:\Users\HP\AppData\Local\Temp\tmpwjjugmhn\model\data\model\assets]
